Workbook
Name Territories: '1) Data entry'!$G$9
Name Deal_Size: '1) Data entry'!$G$11
Name Loaded_Salary: '1) Data entry'!$G$15
Name Travel_Per_Salesperson: '1) Data entry'!$G$19
Name Commission_Rate: '1) Data entry'!$G$28
Name Opportunities_Capacity: '1) Data entry'!$G$31
Name Cycle_Months: '1) Data entry'!$G$33
Name Ramp_Months: '1) Data entry'!$G$35
Name Close_Rate: '1) Data entry'!$G$37
Name Sales_Overhead: '1) Data entry'!$G$41
Name Marketing: '1) Data entry'!$G$48
Name Cost_Of_Revenue_Pct: '1) Data entry'!$G$59
Name RnD_Pct: '1) Data entry'!$G$60
Name GnA_Pct: '1) Data entry'!$G$61

Sheet Orientation
B1: Sales and Marketing Efficiency Modeling Tool
B2: © 2000–2026 Growth Enablement. All rights reserved. Sales Capacity Model: originated 2000, accuracy audit by Ernst & Young 2003, this edition 2026.
B4: Overview: This worksheet is intended to provide you with visibility into your sales and marketing activities. This model helps you examine four business scenarios that can help you improve your business performance: increase the size of your sales force, increase your sales organization’s close rate, decrease your sales cycle time, or increase your average order size. By entering historical and assumptive data, you will be able to determine the impact of each of these investment decisions on your top line revenue and bottom line performance. For example, a 10% decrease in your sales force, coupled with a 10% improvement in your average order size could increase your top line revenue by 7%, but increase your operating margin by almost 800%. Finally, this tool will help you identify the challenges you must overcome to achieve success in each of the business scenarios and provide you with a better framework to assess current and future sales and marketing investments.
B6: It is broken down into the following sections: 1) Data entry - enter historical data and metrics assumptions about your sales and marketing performance. 2) Performance breakdown - a what-if tool that allows you to determine the impact of incremental improvements in your sales and marketing activities. 3) Impact Analysis - highlights the potential impact on your Income Statement by making incremental improvements. 4) Scenario Diagnostic - Lists common are obstacles that stand in the way of achieving your intended results for each scenario.
B8: A Few Points: This is a generic tool intended to give you insight into your sales and marketing mechanics. For a more complete analysis, we recommend that you perform this assessment for each of your sales channels and product lines. Also, there are attributes about your business that are different from others. This model can be tailored to your company. Finally, "increase leads" is not listed as a business scenario because we consider lead generation to be a more leveraged way to conduct sales prospecting. The number of leads, how to acquire them, and how much you can invest to acquire those leads are all handled in the tactical "drill down" spreadsheets that accompany this model.
B10: Using this workbook
B11: 1) Data entry: type what you have into the yellow cells. Grey cells are calculated; the blue column is the value the model uses. Where a line can be entered or calculated, a figure in the yellow cell is used, otherwise the calculation from the lines beneath it.
B12: 2) Performance breakdown: the four scenario sizes are yellow cells at the top. Each scenario changes one input by its size and carries it through the same chain; the two combined columns reuse them.
B13: 3) Impact Analysis: the income statement for the baseline and each scenario, with the percentage net gain and sales and marketing ROI.
B14: Compare: for each scenario, the drivers it changed beside what each change did to operating income (a bridge that balances), and a saved run to compare with the next one, input by input and result by result.
B15: 4) Scenario Diagnostic: for each scenario, the common issues that stand between a company and the improvement.
B16: Formulas are locked; inputs are not. Protection has no password: Review > Unprotect Sheet removes it. Every calculated row states its rule in the last column.
... B20: Blue: value the model uses

Sheet 1) Data entry
B2: Sales and Marketing Efficiency Model
B3: © 2000–2026 Growth Enablement. All rights reserved. Sales Capacity Model: originated 2000, accuracy audit by Ernst & Young 2003, this edition 2026.
B4: Directions. Use this spreadsheet to enter your historical data or assumptions to help you determine your sales and marketing performance. Cells that are yellow and areas where you should input your own data. The data currently populated in each cell is based on industry averages for this fictitious company.
B5: How to fill this in: yellow cells are yours to type; grey cells are calculated; the blue column is the value the model uses. Where a line can be entered or calculated, a figure typed in the yellow cell is used; otherwise the calculation from the lines beneath it is used. A blank is treated as missing, never as zero: enter 0 where an amount is truly zero. Results that depend on a missing value show Incomplete; a scenario that pushes a close rate above 100% or a cycle to zero shows Invalid. Deal size, transactions, revenue and salary are checked against the company's own figures on 2) Performance breakdown (Model checks).
B6: =IF(COUNT(Territories,Deal_Size,Loaded_Salary,Travel_Per_Salesperson,Commission_Rate,Opportunities_Capacity,Cycle_Months,Ramp_Months,Close_Rate,Sales_Overhead,Marketing,Cost_Of_Revenue_Pct,RnD_Pct,GnA_Pct)=14,"Status: complete. Every value the model reads has been entered.","Status: INCOMPLETE. No value for: "&MID(IF(ISNUMBER(Territories),"","; number of sales territories")&IF(ISNUMBER(Deal_Size),"","; average revenue per sales transaction")&IF(ISNUMBER(Loaded_Salary),"","; average fully loaded salary")&IF(ISNUMBER(Travel_Per_Salesperson),"","; average travel costs per salesperson")&IF(ISNUMBER(Commission_Rate),"","; commission")&IF(ISNUMBER(Opportunities_Capacity),"","; opportunities manageable at one time")&IF(ISNUMBER(Cycle_Months),"","; length of sales cycle")&IF(ISNUMBER(Ramp_Months),"","; sales ramp up time")&IF(ISNUMBER(Close_Rate),"","; close rate")&IF(ISNUMBER(Sales_Overhead),"","; sales overhead costs")&IF(ISNUMBER(Marketing),"","; marketing costs")&IF(ISNUMBER(Cost_Of_Revenue_Pct),"","; cost of revenue ratio")&IF(ISNUMBER(RnD_Pct),"","; R&D ratio")&IF(ISNUMBER(GnA_Pct),"","; G&A ratio"),3,2000)&". Results that depend on these show Incomplete.")
B7: Data element | C7: Description | D7: Unit | E7: Entry | F7: Calculated | G7: Value used | H7: Where to find it
B8: Individual Sales Representative Data
B9: Number of sales territories | C9: Enter the number of open sales territories you had last year. This is not based on individual people, so if someone has left the company, but the territory is still open, count that as a sales territory. | D9: count | G9: =IF(E9="","",E9) | H9: Territory plan or sales operations
B11: Average revenue per sales transaction | C11: This is the average deal size for your company. For this simple analysis, you can get this figure by dividing your revenue by total number of contracts. For more detailed analysis, we recommend that you break things down into product lines, services offerings, and sales channels. You should also separate new client revenue from upselling your installed base. For professional services, credit the total esimated hours for a project towards one sales transaction. | D11: $ | F11: =IF(COUNT(E12:E13)=0,"",IF(COUNT(E12:E13)<ROWS(E12:E13),"Incomplete",IFERROR(E13/E12,"n/a"))) | G11: =IF(E11<>"",E11,F11) | H11: Finance: revenue ÷ contracts, or CRM closed-won report
C12: Number of contracts last year | D12: count | H12: Billing or contract system
C13: Revenue from those contract | D13: $ | H13: Income statement
B15: Average fully loaded salary | C15: To help develop the most effective market development effort, we must better understand our cost of sales and what drives them. Right now we are focusing on the salaries of the sales team only. Do not count salaries of non-quota carrying managers, sales engineers, or other executives. Your CFO should know what your benefits load rate is. This metric assumes a fully loaded resource (insurance, 401K, FICA, allocation of overhead, etc). | D15: $ | F15: =IF(COUNT(E16:E17)=0,"",IF(COUNT(E16:E17)<ROWS(E16:E17),"Incomplete",IFERROR(E16+(E16*E17),"n/a"))) | G15: =IF(E15<>"",E15,F15) | H15: Payroll and benefits ledger, quota-carrying roles only
C16: Average salary per sales rep | D16: $ | H16: Payroll register
C17: Corporate load rate | D17: % | H17: Benefits ledger ÷ base payroll
B19: Average travel costs per rep | C19: Most CFO's track overall travel expenses and try to reduce costs by limiting per diems, hotel expenses, etc. However, the real driver is a sales call. Sales people only incur these travel costs on the road. The best way to reduce travel costs is to get a better return out of each sales trip. Oftentimes, sales people will go on multiple client site visits to gain information easily gathered over the phone, or to have meetings with buyers who lack the right marketing materials to decide to buy your solution. Below are the elements of a sales trip. Estimate the costs assumed for each sales trip. Again, only assume the cost of a single sales person. Sales engineers and other costs are too complex for simple analysis. | D19: $ | F19: =IF(COUNT(E20:E26)=0,"",IF(COUNT(E20:E26)<ROWS(E20:E26),"Incomplete",IFERROR((($E$20+$E$21+$E$25)+($E$24*($E$22+$E$23)))*$E$26,"n/a"))) | G19: =IF(E19<>"",E19,F19) | H19: T&E ledger for quota-carrying salespeople ÷ salespeople
C20: Travel (air fare, train, mileage round trip) | D20: $ | H20: Expense reports
C21: Cabs, tolls, car rentals (etc) | D21: $ | H21: Expense reports
C22: Meals (breakfast, lunch, dinner) per day | D22: $ | H22: Expense policy or reports
C23: Lodging (per night average room expense) | D23: $ | H23: Expense policy or reports
C24: Days gone per trip | D24: count | H24: Calendars or expense reports
C25: Entertainment (client dinners, lunch, movies, etc.) per each trip | D25: $ | H25: Expense reports
C26: Trips per year | D26: count | H26: Calendars or expense reports
B28: Commission | C28: Commissions are the most logical and well understood driver of variable sales costs. Simply enter your sales forces average commission. Again, for simple analysis - just use an average. This model can be modified to accommodate your whole compensation plan. | D28: % | G28: =IF(E28="","",E28) | H28: Compensation plan, or commissions paid ÷ revenue
B30: Sales Mechanics
B31: Number of pipeline opportunities manageable at one time | C31: One driver of sales force inefficiency is the amount of NON-selling time spent by sales people. Some companies estimate as much at 50% of their time is invested in "non-selling" activities. Our studies reveal that a larger portion of that time in spend in activitity that isn't value-added to customers. The best way to financially measure that impact is by monitoring the number of accounts any given sales person can effectively manage at the same time. The greater amount of time you allow your sales people to sell - the more opportunities they can work in a given year. | D31: count | G31: =IF(E31="","",E31) | H31: Sales leadership; test against CRM load per salesperson
B33: Length of sales cycle (in months) | C33: Tracks how long from when a qualified opportunity enters the pipeline to when it closes as a sale. Your sales process may have many steps, so for simplicity track the time it takes from first meeting to the date the agreement is received by accounting. Most organizations do not track this information, so if you do not have the data - make an estimate. The single greatest impact you can have on your business is to shorten your sales cycle times. | D33: months | G33: =IF(E33="","",E33) | H33: CRM closed-won report (median)
B35: Sales ramp up time (in months) | C35: How long does it take to get a new sales person up to speed to where they are operating at maximum efficiency? Most high tech companies do a good job of training sales people on what their products are, but do very little to help them understand WHY the product is important or how to sell it. This leads to lengthy "ramp up" times. We recommend getting this figure from a sales manager. | D35: months | G35: =IF(E35="","",E35) | H35: Sales management; productivity by tenure
B37: close rate | C37: This certainly can mean a lot of things to different people. Here we want to understand the effectiveness of how well your organization manages the sales process from first sales meeting to eventual close. Please estimate the percentage of all of the pipeline opportunities that your organization has worked that have resulted in an executed agreement. | D37: % | G37: =IF(E37="","",E37) | H37: CRM closed-opportunity report
B38: Overhead, Management, and Marketing Costs
B39: Total Sales Overhead and Marketing Costs | C39: Total of the two sections below (calculated; not an entry). | D39: $ | F39: =IF(AND(ISNUMBER(G41),ISNUMBER(G48)),G41+G48,"Incomplete") | H39: Calculated
B41: Sales Overhead Costs | C41: This tracks all of the non-variable costs associated with running a sales organization, and includes executive salaries, sales support, training, and performance plans. | D41: $ | F41: =IF(COUNT(E42:E46)=0,"",IF(COUNT(E42:E46)<ROWS(E42:E46),"Incomplete",IFERROR(E42+E43+E44+E45+E46,"n/a"))) | G41: =IF(E41<>"",E41,F41) | H41: General ledger: sales cost centers
C42: Total Non-quota carrying sales manager salaries | D42: $ | H42: Payroll
C43: Sales engineers or other non-quota sales support personnel | D43: $ | H43: Payroll
C44: Sales administrative personnel (Sales operations, sales Admins) | D44: $ | H44: Payroll
C45: Training costs (total expenses related to training, travel for training, and all headcount associated) | D45: $ | H45: General ledger
C46: Incentive costs (non-quota related commissions, President's Club costs, etc) | D46: $ | H46: General ledger
B48: Marketing Costs | C48: This tracks all of the overall investments the company makes to help drive revenue. Marketing resources are extremely important to consider because in most organizations the sales and marketing departments are not coordinated and this results in tremendous waste. | D48: $ | F48: =IF(COUNT(E49:E56)=0,"",IF(COUNT(E49:E56)<ROWS(E49:E56),"Incomplete",IFERROR(E49+E50+E51+E54+E55+E56+E52+E53,"n/a"))) | G48: =IF(E48<>"",E48,F48) | H48: General ledger: marketing cost centers
C49: All marketing personnel | D49: $ | H49: Payroll
C50: Web site investments and maintenance | D50: $ | H50: General ledger
C51: Events - online and roadshows | D51: $ | H51: General ledger
...

Sheet 2) Performance breakdown
B2: "What If" Performance Breakdown
B3: © 2000–2026 Growth Enablement. All rights reserved. Sales Capacity Model: originated 2000, accuracy audit by Ernst & Young 2003, this edition 2026.
B4: ='1) Data entry'!B6&IF(COUNT(E7:H7)=COLUMNS(E7:H7),""," Scenario sizes: INCOMPLETE (a size in row 7 is blank); those scenarios show Incomplete.")
B5: Scenario | C5: Baseline | E5: Individual Scenarios | J5: Combined | L5: How it is calculated
E6: Hire more sales people | F6: Increase Close Rate | G6: Decrease Sales Cycle Time | H6: Increase Average Revenue/ Transaction | J6: Increase close and deal size; decrease cycle | K6: Improve all scenarios
B7: Size of improvement (relative, e.g. 0.10 = 10%) | E7: 0.1 | F7: 0.1 | G7: 0.1 | H7: 0.1 | J7: uses the three quality sizes | K7: uses all four | L7: Each scenario applies its size to one input and leaves the rest at baseline
B8: Individual Sales Representative Data
B9: ='1) Data entry'!B9 | C9: =IF(ISNUMBER(Territories),IFERROR(Territories,"n/a"),IF(Territories="Invalid","Invalid","Incomplete")) | E9: =IF(AND(ISNUMBER(C9),ISNUMBER(E7)),IFERROR((C9*E7)+C9,"n/a"),IF(OR(C9="Invalid",E7="Invalid"),"Invalid","Incomplete")) | F9: =IF(ISNUMBER(C9),IFERROR(C9,"n/a"),IF(C9="Invalid","Invalid","Incomplete")) | G9: =IF(ISNUMBER(C9),IFERROR(C9,"n/a"),IF(C9="Invalid","Invalid","Incomplete")) | H9: =IF(ISNUMBER(C9),IFERROR(C9,"n/a"),IF(C9="Invalid","Invalid","Incomplete")) | J9: =IF(ISNUMBER(C9),IFERROR(C9,"n/a"),IF(C9="Invalid","Invalid","Incomplete")) | K9: =IF(ISNUMBER(E9),IFERROR(E9,"n/a"),IF(E9="Invalid","Invalid","Incomplete")) | L9: Territories from the entry sheet; the hiring scenario adds the chosen share
B10: ='1) Data entry'!B11 | C10: =IF(ISNUMBER(Deal_Size),IFERROR(Deal_Size,"n/a"),IF(Deal_Size="Invalid","Invalid","Incomplete")) | E10: =IF(ISNUMBER(C10),IFERROR(C10,"n/a"),IF(C10="Invalid","Invalid","Incomplete")) | F10: =IF(ISNUMBER(C10),IFERROR(C10,"n/a"),IF(C10="Invalid","Invalid","Incomplete")) | G10: =IF(ISNUMBER(C10),IFERROR(C10,"n/a"),IF(C10="Invalid","Invalid","Incomplete")) | H10: =IF(AND(ISNUMBER(G10),ISNUMBER(H7)),IFERROR(G10+(G10*H7),"n/a"),IF(OR(G10="Invalid",H7="Invalid"),"Invalid","Incomplete")) | J10: =IF(ISNUMBER(H10),IFERROR(H10,"n/a"),IF(H10="Invalid","Invalid","Incomplete")) | K10: =IF(ISNUMBER(J10),IFERROR(J10,"n/a"),IF(J10="Invalid","Invalid","Incomplete")) | L10: Deal size from the entry sheet; the deal size scenario adds the chosen share
B11: ='1) Data entry'!B15 | C11: =IF(ISNUMBER(Loaded_Salary),IFERROR(Loaded_Salary,"n/a"),IF(Loaded_Salary="Invalid","Invalid","Incomplete")) | E11: =IF(ISNUMBER(C11),IFERROR(C11,"n/a"),IF(C11="Invalid","Invalid","Incomplete")) | F11: =IF(ISNUMBER(C11),IFERROR(C11,"n/a"),IF(C11="Invalid","Invalid","Incomplete")) | G11: =IF(ISNUMBER(C11),IFERROR(C11,"n/a"),IF(C11="Invalid","Invalid","Incomplete")) | H11: =IF(ISNUMBER(C11),IFERROR(C11,"n/a"),IF(C11="Invalid","Invalid","Incomplete")) | J11: =IF(ISNUMBER(C11),IFERROR(C11,"n/a"),IF(C11="Invalid","Invalid","Incomplete")) | K11: =IF(ISNUMBER(J11),IFERROR(J11,"n/a"),IF(J11="Invalid","Invalid","Incomplete")) | L11: Fully loaded salary from the entry sheet (value used)
B12: ='1) Data entry'!B19 | C12: =IF(ISNUMBER(Travel_Per_Salesperson),IFERROR(Travel_Per_Salesperson,"n/a"),IF(Travel_Per_Salesperson="Invalid","Invalid","Incomplete")) | E12: =IF(ISNUMBER(C12),IFERROR(C12,"n/a"),IF(C12="Invalid","Invalid","Incomplete")) | F12: =IF(ISNUMBER(C12),IFERROR(C12,"n/a"),IF(C12="Invalid","Invalid","Incomplete")) | G12: =IF(ISNUMBER(C12),IFERROR(C12,"n/a"),IF(C12="Invalid","Invalid","Incomplete")) | H12: =IF(ISNUMBER(C12),IFERROR(C12,"n/a"),IF(C12="Invalid","Invalid","Incomplete")) | J12: =IF(ISNUMBER(C12),IFERROR(C12,"n/a"),IF(C12="Invalid","Invalid","Incomplete")) | K12: =IF(ISNUMBER(J12),IFERROR(J12,"n/a"),IF(J12="Invalid","Invalid","Incomplete")) | L12: Travel per salesperson from the entry sheet
B13: ='1) Data entry'!B28 | C13: =IF(AND(ISNUMBER(C23),ISNUMBER(Commission_Rate)),IFERROR(C23*Commission_Rate,"n/a"),IF(OR(C23="Invalid",Commission_Rate="Invalid"),"Invalid","Incomplete")) | E13: =IF(AND(ISNUMBER(E23),ISNUMBER(Commission_Rate)),IFERROR(E23*Commission_Rate,"n/a"),IF(OR(E23="Invalid",Commission_Rate="Invalid"),"Invalid","Incomplete")) | F13: =IF(AND(ISNUMBER(F23),ISNUMBER(Commission_Rate)),IFERROR(F23*Commission_Rate,"n/a"),IF(OR(F23="Invalid",Commission_Rate="Invalid"),"Invalid","Incomplete")) | G13: =IF(AND(ISNUMBER(G23),ISNUMBER(Commission_Rate)),IFERROR(G23*Commission_Rate,"n/a"),IF(OR(G23="Invalid",Commission_Rate="Invalid"),"Invalid","Incomplete")) | H13: =IF(AND(ISNUMBER(H23),ISNUMBER(Commission_Rate)),IFERROR(H23*Commission_Rate,"n/a"),IF(OR(H23="Invalid",Commission_Rate="Invalid"),"Invalid","Incomplete")) | J13: =IF(AND(ISNUMBER(J23),ISNUMBER(Commission_Rate)),IFERROR(J23*Commission_Rate,"n/a"),IF(OR(J23="Invalid",Commission_Rate="Invalid"),"Invalid","Incomplete")) | K13: =IF(AND(ISNUMBER(K23),ISNUMBER(Commission_Rate)),IFERROR(K23*Commission_Rate,"n/a"),IF(OR(K23="Invalid",Commission_Rate="Invalid"),"Invalid","Incomplete")) | L13: Commission = revenue per salesperson (row 23) × commission rate
B14: Total cost per sales rep | C14: =IF(COUNT(C11:C13)=ROWS(C11:C13)*COLUMNS(C11:C13),IFERROR(SUM(C11:C13),"n/a"),IF(COUNTIF(C11:C13,"Invalid")>0,"Invalid","Incomplete")) | E14: =IF(COUNT(E11:E13)=ROWS(E11:E13)*COLUMNS(E11:E13),IFERROR(SUM(E11:E13),"n/a"),IF(COUNTIF(E11:E13,"Invalid")>0,"Invalid","Incomplete")) | F14: =IF(COUNT(F11:F13)=ROWS(F11:F13)*COLUMNS(F11:F13),IFERROR(SUM(F11:F13),"n/a"),IF(COUNTIF(F11:F13,"Invalid")>0,"Invalid","Incomplete")) | G14: =IF(COUNT(G11:G13)=ROWS(G11:G13)*COLUMNS(G11:G13),IFERROR(SUM(G11:G13),"n/a"),IF(COUNTIF(G11:G13,"Invalid")>0,"Invalid","Incomplete")) | H14: =IF(COUNT(H11:H13)=ROWS(H11:H13)*COLUMNS(H11:H13),IFERROR(SUM(H11:H13),"n/a"),IF(COUNTIF(H11:H13,"Invalid")>0,"Invalid","Incomplete")) | J14: =IF(COUNT(J11:J13)=ROWS(J11:J13)*COLUMNS(J11:J13),IFERROR(SUM(J11:J13),"n/a"),IF(COUNTIF(J11:J13,"Invalid")>0,"Invalid","Incomplete")) | K14: =IF(ISNUMBER(J14),IFERROR(J14,"n/a"),IF(J14="Invalid","Invalid","Incomplete")) | L14: Salary + travel + commission
B15: Sales Mechanics
B16: Number of pipeline opportunities manageable at one time | C16: =IF(ISNUMBER(Opportunities_Capacity),IFERROR(Opportunities_Capacity,"n/a"),IF(Opportunities_Capacity="Invalid","Invalid","Incomplete")) | E16: =IF(ISNUMBER(C16),IFERROR(C16,"n/a"),IF(C16="Invalid","Invalid","Incomplete")) | F16: =IF(ISNUMBER(C16),IFERROR(C16,"n/a"),IF(C16="Invalid","Invalid","Incomplete")) | G16: =IF(ISNUMBER(C16),IFERROR(C16,"n/a"),IF(C16="Invalid","Invalid","Incomplete")) | H16: =IF(ISNUMBER(C16),IFERROR(C16,"n/a"),IF(C16="Invalid","Invalid","Incomplete")) | J16: =IF(ISNUMBER(C16),IFERROR(C16,"n/a"),IF(C16="Invalid","Invalid","Incomplete")) | K16: =IF(ISNUMBER(J16),IFERROR(J16,"n/a"),IF(J16="Invalid","Invalid","Incomplete")) | L16: Opportunities a salesperson can manage at once, from the entry sheet
B17: Length of sales cycle (in months) | C17: =IF(ISNUMBER(Cycle_Months),IFERROR(IF((Cycle_Months)<=0,"Invalid",Cycle_Months),"n/a"),IF(Cycle_Months="Invalid","Invalid","Incomplete")) | E17: =IF(ISNUMBER(C17),IFERROR(IF((C17)<=0,"Invalid",C17),"n/a"),IF(C17="Invalid","Invalid","Incomplete")) | F17: =IF(ISNUMBER(C17),IFERROR(IF((C17)<=0,"Invalid",C17),"n/a"),IF(C17="Invalid","Invalid","Incomplete")) | G17: =IF(AND(ISNUMBER(C17),ISNUMBER(G7)),IFERROR(IF((C17-(C17*G7))<=0,"Invalid",C17-(C17*G7)),"n/a"),IF(OR(C17="Invalid",G7="Invalid"),"Invalid","Incomplete")) | H17: =IF(ISNUMBER(C17),IFERROR(IF((C17)<=0,"Invalid",C17),"n/a"),IF(C17="Invalid","Invalid","Incomplete")) | J17: =IF(ISNUMBER(G17),IFERROR(IF((G17)<=0,"Invalid",G17),"n/a"),IF(G17="Invalid","Invalid","Incomplete")) | K17: =IF(ISNUMBER(J17),IFERROR(IF((J17)<=0,"Invalid",J17),"n/a"),IF(J17="Invalid","Invalid","Incomplete")) | L17: Sales cycle from the entry sheet; the cycle scenario removes the chosen share
B18: Sales ramp up time (in months) | C18: =IF(ISNUMBER(Ramp_Months),IFERROR(Ramp_Months,"n/a"),IF(Ramp_Months="Invalid","Invalid","Incomplete")) | E18: =IF(ISNUMBER(C18),IFERROR(C18,"n/a"),IF(C18="Invalid","Invalid","Incomplete")) | F18: =IF(ISNUMBER(C18),IFERROR(C18,"n/a"),IF(C18="Invalid","Invalid","Incomplete")) | G18: =IF(ISNUMBER(C18),IFERROR(C18,"n/a"),IF(C18="Invalid","Invalid","Incomplete")) | H18: =IF(ISNUMBER(C18),IFERROR(C18,"n/a"),IF(C18="Invalid","Invalid","Incomplete")) | J18: =IF(ISNUMBER(C18),IFERROR(C18,"n/a"),IF(C18="Invalid","Invalid","Incomplete")) | K18: =IF(ISNUMBER(C18),IFERROR(C18,"n/a"),IF(C18="Invalid","Invalid","Incomplete")) | L18: Ramp time from the entry sheet
B19: close rate | C19: =IF(ISNUMBER(Close_Rate),IFERROR(IF((Close_Rate)>1,"Invalid",Close_Rate),"n/a"),IF(Close_Rate="Invalid","Invalid","Incomplete")) | E19: =IF(ISNUMBER(C19),IFERROR(IF((C19)>1,"Invalid",C19),"n/a"),IF(C19="Invalid","Invalid","Incomplete")) | F19: =IF(AND(ISNUMBER(C19),ISNUMBER(F7)),IFERROR(IF(((C19*F7)+C19)>1,"Invalid",(C19*F7)+C19),"n/a"),IF(OR(C19="Invalid",F7="Invalid"),"Invalid","Incomplete")) | G19: =IF(ISNUMBER(C19),IFERROR(IF((C19)>1,"Invalid",C19),"n/a"),IF(C19="Invalid","Invalid","Incomplete")) | H19: =IF(ISNUMBER(C19),IFERROR(IF((C19)>1,"Invalid",C19),"n/a"),IF(C19="Invalid","Invalid","Incomplete")) | J19: =IF(ISNUMBER(F19),IFERROR(IF((F19)>1,"Invalid",F19),"n/a"),IF(F19="Invalid","Invalid","Incomplete")) | K19: =IF(ISNUMBER(J19),IFERROR(IF((J19)>1,"Invalid",J19),"n/a"),IF(J19="Invalid","Invalid","Incomplete")) | L19: Close rate from the entry sheet; the close rate scenario adds the chosen share
B20: Individual Impact
B21: Maximum number of opportunities to pursue / year | C21: =IF(AND(ISNUMBER(C17),ISNUMBER(C16)),IFERROR((12/C17)*C16,"n/a"),IF(OR(C17="Invalid",C16="Invalid"),"Invalid","Incomplete")) | E21: =IF(AND(ISNUMBER(E17),ISNUMBER(E16)),IFERROR((12/E17)*E16,"n/a"),IF(OR(E17="Invalid",E16="Invalid"),"Invalid","Incomplete")) | F21: =IF(AND(ISNUMBER(F17),ISNUMBER(F16)),IFERROR((12/F17)*F16,"n/a"),IF(OR(F17="Invalid",F16="Invalid"),"Invalid","Incomplete")) | G21: =IF(AND(ISNUMBER(G17),ISNUMBER(G16)),IFERROR((12/G17)*G16,"n/a"),IF(OR(G17="Invalid",G16="Invalid"),"Invalid","Incomplete")) | H21: =IF(AND(ISNUMBER(H17),ISNUMBER(H16)),IFERROR((12/H17)*H16,"n/a"),IF(OR(H17="Invalid",H16="Invalid"),"Invalid","Incomplete")) | J21: =IF(AND(ISNUMBER(J17),ISNUMBER(J16)),IFERROR((12/J17)*J16,"n/a"),IF(OR(J17="Invalid",J16="Invalid"),"Invalid","Incomplete")) | K21: =IF(ISNUMBER(J21),IFERROR(J21,"n/a"),IF(J21="Invalid","Invalid","Incomplete")) | L21: Opportunities a salesperson can pursue in a year = (12 ÷ cycle) × opportunities managed at once
B22: Number of annual sales transactions per year / rep | C22: =IF(AND(ISNUMBER(C21),ISNUMBER(C19)),IFERROR(C21*C19,"n/a"),IF(OR(C21="Invalid",C19="Invalid"),"Invalid","Incomplete")) | E22: =IF(ISNUMBER(C22),IFERROR(C22,"n/a"),IF(C22="Invalid","Invalid","Incomplete")) | F22: =IF(AND(ISNUMBER(F21),ISNUMBER(F19)),IFERROR(F21*F19,"n/a"),IF(OR(F21="Invalid",F19="Invalid"),"Invalid","Incomplete")) | G22: =IF(AND(ISNUMBER(G21),ISNUMBER(G19)),IFERROR(G21*G19,"n/a"),IF(OR(G21="Invalid",G19="Invalid"),"Invalid","Incomplete")) | H22: =IF(AND(ISNUMBER(H21),ISNUMBER(H19)),IFERROR(H21*H19,"n/a"),IF(OR(H21="Invalid",H19="Invalid"),"Invalid","Incomplete")) | J22: =IF(AND(ISNUMBER(J21),ISNUMBER(J19)),IFERROR(J21*J19,"n/a"),IF(OR(J21="Invalid",J19="Invalid"),"Invalid","Incomplete")) | K22: =IF(ISNUMBER(J22),IFERROR(J22,"n/a"),IF(J22="Invalid","Invalid","Incomplete")) | L22: Transactions per salesperson = opportunities pursued × close rate
B23: Average annual revenue per rep | C23: =IF(AND(ISNUMBER(C22),ISNUMBER(C10)),IFERROR(C22*C10,"n/a"),IF(OR(C22="Invalid",C10="Invalid"),"Invalid","Incomplete")) | E23: =IF(AND(ISNUMBER(E22),ISNUMBER(E10)),IFERROR(E22*E10,"n/a"),IF(OR(E22="Invalid",E10="Invalid"),"Invalid","Incomplete")) | F23: =IF(AND(ISNUMBER(F22),ISNUMBER(F10)),IFERROR(F22*F10,"n/a"),IF(OR(F22="Invalid",F10="Invalid"),"Invalid","Incomplete")) | G23: =IF(AND(ISNUMBER(G22),ISNUMBER(G10)),IFERROR(G22*G10,"n/a"),IF(OR(G22="Invalid",G10="Invalid"),"Invalid","Incomplete")) | H23: =IF(AND(ISNUMBER(H22),ISNUMBER(H10)),IFERROR(H22*H10,"n/a"),IF(OR(H22="Invalid",H10="Invalid"),"Invalid","Incomplete")) | J23: =IF(AND(ISNUMBER(J22),ISNUMBER(J10)),IFERROR(J22*J10,"n/a"),IF(OR(J22="Invalid",J10="Invalid"),"Invalid","Incomplete")) | K23: =IF(ISNUMBER(J23),IFERROR(J23,"n/a"),IF(J23="Invalid","Invalid","Incomplete")) | L23: Revenue per salesperson = transactions × deal size
B24: Outcomes
B25: Total revenues | C25: =IF(AND(ISNUMBER(C23),ISNUMBER(C9)),IFERROR(C23*C9,"n/a"),IF(OR(C23="Invalid",C9="Invalid"),"Invalid","Incomplete")) | E25: =IF(AND(ISNUMBER(E18),ISNUMBER(E23),ISNUMBER(E9),ISNUMBER(C9),ISNUMBER(C25)),IFERROR(((((12-E18)/12)*E23)*(E9-C9))+C25,"n/a"),IF(OR(E18="Invalid",E23="Invalid",E9="Invalid",C9="Invalid",C25="Invalid"),"Invalid","Incomplete")) | F25: =IF(AND(ISNUMBER(F23),ISNUMBER(F9)),IFERROR(F23*F9,"n/a"),IF(OR(F23="Invalid",F9="Invalid"),"Invalid","Incomplete")) | G25: =IF(AND(ISNUMBER(G23),ISNUMBER(G9)),IFERROR(G23*G9,"n/a"),IF(OR(G23="Invalid",G9="Invalid"),"Invalid","Incomplete")) | H25: =IF(AND(ISNUMBER(H23),ISNUMBER(H9)),IFERROR(H23*H9,"n/a"),IF(OR(H23="Invalid",H9="Invalid"),"Invalid","Incomplete")) | J25: =IF(AND(ISNUMBER(J23),ISNUMBER(J9)),IFERROR((J23*J9),"n/a"),IF(OR(J23="Invalid",J9="Invalid"),"Invalid","Incomplete")) | K25: =IF(AND(ISNUMBER(K23),ISNUMBER(K9),ISNUMBER(E18),ISNUMBER(E23),ISNUMBER(E9),ISNUMBER(C9)),IFERROR((K23*K9)-((((12-E18)/12)*E23)*(E9-C9)),"n/a"),IF(OR(K23="Invalid",K9="Invalid",E18="Invalid",E23="Invalid",E9="Invalid",C9="Invalid"),"Invalid","Incomplete")) | L25: Revenue = revenue per salesperson × territories. Hiring: added territories earn (12 − ramp) ÷ 12 of a year. Improve all: the same credit is deducted once
B26: Total Sales Rep. Costs | C26: =IF(AND(ISNUMBER(C14),ISNUMBER(C9)),IFERROR(C14*C9,"n/a"),IF(OR(C14="Invalid",C9="Invalid"),"Invalid","Incomplete")) | E26: =IF(AND(ISNUMBER(E14),ISNUMBER(E9)),IFERROR(E14*E9,"n/a"),IF(OR(E14="Invalid",E9="Invalid"),"Invalid","Incomplete")) | F26: =IF(AND(ISNUMBER(F14),ISNUMBER(F9)),IFERROR(F14*F9,"n/a"),IF(OR(F14="Invalid",F9="Invalid"),"Invalid","Incomplete")) | G26: =IF(AND(ISNUMBER(G14),ISNUMBER(G9)),IFERROR(G14*G9,"n/a"),IF(OR(G14="Invalid",G9="Invalid"),"Invalid","Incomplete")) | H26: =IF(AND(ISNUMBER(H14),ISNUMBER(H9)),IFERROR(H14*H9,"n/a"),IF(OR(H14="Invalid",H9="Invalid"),"Invalid","Incomplete")) | J26: =IF(AND(ISNUMBER(J14),ISNUMBER(J9)),IFERROR(J14*J9,"n/a"),IF(OR(J14="Invalid",J9="Invalid"),"Invalid","Incomplete")) | K26: =IF(AND(ISNUMBER(K14),ISNUMBER(K9)),IFERROR(K14*K9,"n/a"),IF(OR(K14="Invalid",K9="Invalid"),"Invalid","Incomplete")) | L26: Salesperson costs = cost per salesperson × territories
B28: This spreadsheet is designed to help you determine the impact of making incremental performance gains across the four business improvement scenarios. Changes in the yellow cells will drive results throughout the entire workbook.
B30: Model checks: does the baseline reproduce what the company knows about last year? | C30: Model | E30: Company figure | F30: Difference | G30: Difference % | H30: Check | L30: What a difference points to
B31: Deal size | C31: =IF(ISNUMBER(Deal_Size),IFERROR(Deal_Size,"n/a"),IF(Deal_Size="Invalid","Invalid","Incomplete")) | E31: =IF(ISNUMBER('1) Data entry'!F11),'1) Data entry'!F11,"") | F31: =IF(AND(ISNUMBER(C31),ISNUMBER(E31)),C31-E31,"") | G31: =IF(AND(ISNUMBER(C31),ISNUMBER(E31)),IF(E31=0,"n/a",(C31-E31)/E31),"") | H31: =IF(NOT(ISNUMBER(C31)),C31,IF(NOT(ISNUMBER(E31)),"No figure",IF(ROUND(C31,0)=ROUND(E31,0),"Agrees","Differs"))) | L31: Deal size used vs revenue ÷ contracts (entry sheet, rows 11–13). If they differ: the deal size entered, or the contracts and revenue figures.
B32: Transactions per year | C32: =IF(AND(ISNUMBER(C22),ISNUMBER(C9)),IFERROR(C22*C9,"n/a"),IF(OR(C22="Invalid",C9="Invalid"),"Invalid","Incomplete")) | E32: =IF(ISNUMBER('1) Data entry'!E12),'1) Data entry'!E12,"") | F32: =IF(AND(ISNUMBER(C32),ISNUMBER(E32)),C32-E32,"") | G32: =IF(AND(ISNUMBER(C32),ISNUMBER(E32)),IF(E32=0,"n/a",(C32-E32)/E32),"") | H32: =IF(NOT(ISNUMBER(C32)),C32,IF(NOT(ISNUMBER(E32)),"No figure",IF(ROUND(C32,0)=ROUND(E32,0),"Agrees","Differs"))) | L32: Baseline transactions (row 22 × territories) vs contracts last year. If they differ: territories, opportunities manageable at once, cycle or close rate.
B33: Revenue | C33: =IF(ISNUMBER(C25),IFERROR(C25,"n/a"),IF(C25="Invalid","Invalid","Incomplete")) | E33: =IF(ISNUMBER('1) Data entry'!E13),'1) Data entry'!E13,"") | F33: =IF(AND(ISNUMBER(C33),ISNUMBER(E33)),C33-E33,"") | G33: =IF(AND(ISNUMBER(C33),ISNUMBER(E33)),IF(E33=0,"n/a",(C33-E33)/E33),"") | H33: =IF(NOT(ISNUMBER(C33)),C33,IF(NOT(ISNUMBER(E33)),"No figure",IF(ROUND(C33,0)=ROUND(E33,0),"Agrees","Differs"))) | L33: Baseline revenue (row 25) vs revenue last year. If transactions agree and revenue does not: deal size.
B34: Fully loaded salary | C34: =IF(ISNUMBER(Loaded_Salary),IFERROR(Loaded_Salary,"n/a"),IF(Loaded_Salary="Invalid","Invalid","Incomplete")) | E34: =IF(ISNUMBER('1) Data entry'!F15),'1) Data entry'!F15,"") | F34: =IF(AND(ISNUMBER(C34),ISNUMBER(E34)),C34-E34,"") | G34: =IF(AND(ISNUMBER(C34),ISNUMBER(E34)),IF(E34=0,"n/a",(C34-E34)/E34),"") | H34: =IF(NOT(ISNUMBER(C34)),C34,IF(NOT(ISNUMBER(E34)),"No figure",IF(ROUND(C34,0)=ROUND(E34,0),"Agrees","Differs"))) | L34: Salary used by the calculations vs base salary × (1 + load rate) (entry sheet, rows 15–17). If they differ: the salary entered, or its components.
B35: These checks use figures the model already asks for. They change no result: a difference is a question about the data, and the equations show which assumption to question.

Sheet 3) Impact Analysis
B2: Financial Impact
B3: © 2000–2026 Growth Enablement. All rights reserved. Sales Capacity Model: originated 2000, accuracy audit by Ernst & Young 2003, this edition 2026.
B4: ='2) Performance breakdown'!B4
E5: Scenario | J5: Combined | L5: How it is calculated
C6: Baseline | E6: Hire more sales people | F6: Increase Close Rate | G6: Decrease Sales Cycle Time | H6: Increase Average Revenue/ Transaction | J6: Increase close and deal size; decrease cycle | K6: Improve all scenarios
B7: Revenue
B8: Total revenues | C8: =IF(ISNUMBER('2) Performance breakdown'!C25),IFERROR('2) Performance breakdown'!C25,"n/a"),IF('2) Performance breakdown'!C25="Invalid","Invalid","Incomplete")) | E8: =IF(ISNUMBER('2) Performance breakdown'!E25),IFERROR('2) Performance breakdown'!E25,"n/a"),IF('2) Performance breakdown'!E25="Invalid","Invalid","Incomplete")) | F8: =IF(ISNUMBER('2) Performance breakdown'!F25),IFERROR('2) Performance breakdown'!F25,"n/a"),IF('2) Performance breakdown'!F25="Invalid","Invalid","Incomplete")) | G8: =IF(ISNUMBER('2) Performance breakdown'!G25),IFERROR('2) Performance breakdown'!G25,"n/a"),IF('2) Performance breakdown'!G25="Invalid","Invalid","Incomplete")) | H8: =IF(ISNUMBER('2) Performance breakdown'!H25),IFERROR('2) Performance breakdown'!H25,"n/a"),IF('2) Performance breakdown'!H25="Invalid","Invalid","Incomplete")) | J8: =IF(ISNUMBER('2) Performance breakdown'!J25),IFERROR('2) Performance breakdown'!J25,"n/a"),IF('2) Performance breakdown'!J25="Invalid","Invalid","Incomplete")) | K8: =IF(ISNUMBER('2) Performance breakdown'!K25),IFERROR('2) Performance breakdown'!K25,"n/a"),IF('2) Performance breakdown'!K25="Invalid","Invalid","Incomplete")) | L8: Total revenues from 2) Performance breakdown, row 25
B9: Increase in revenue from base | E9: =IF(AND(ISNUMBER(E8),ISNUMBER('2) Performance breakdown'!$C$25)),IFERROR(E8-'2) Performance breakdown'!$C$25,"n/a"),IF(OR(E8="Invalid",'2) Performance breakdown'!$C$25="Invalid"),"Invalid","Incomplete")) | F9: =IF(AND(ISNUMBER(F8),ISNUMBER('2) Performance breakdown'!$C$25)),IFERROR(F8-'2) Performance breakdown'!$C$25,"n/a"),IF(OR(F8="Invalid",'2) Performance breakdown'!$C$25="Invalid"),"Invalid","Incomplete")) | G9: =IF(AND(ISNUMBER(G8),ISNUMBER('2) Performance breakdown'!$C$25)),IFERROR(G8-'2) Performance breakdown'!$C$25,"n/a"),IF(OR(G8="Invalid",'2) Performance breakdown'!$C$25="Invalid"),"Invalid","Incomplete")) | H9: =IF(AND(ISNUMBER(H8),ISNUMBER('2) Performance breakdown'!$C$25)),IFERROR(H8-'2) Performance breakdown'!$C$25,"n/a"),IF(OR(H8="Invalid",'2) Performance breakdown'!$C$25="Invalid"),"Invalid","Incomplete")) | J9: =IF(AND(ISNUMBER(J8),ISNUMBER('2) Performance breakdown'!$C$25)),IFERROR(J8-'2) Performance breakdown'!$C$25,"n/a"),IF(OR(J8="Invalid",'2) Performance breakdown'!$C$25="Invalid"),"Invalid","Incomplete")) | K9: =IF(AND(ISNUMBER(K8),ISNUMBER('2) Performance breakdown'!$C$25)),IFERROR(K8-'2) Performance breakdown'!$C$25,"n/a"),IF(OR(K8="Invalid",'2) Performance breakdown'!$C$25="Invalid"),"Invalid","Incomplete")) | L9: Scenario revenue − baseline revenue
B11: Costs
B12: Increase in sales costs | E12: =IF(AND(ISNUMBER('2) Performance breakdown'!E26),ISNUMBER('2) Performance breakdown'!$C$26)),IFERROR('2) Performance breakdown'!E26-'2) Performance breakdown'!$C$26,"n/a"),IF(OR('2) Performance breakdown'!E26="Invalid",'2) Performance breakdown'!$C$26="Invalid"),"Invalid","Incomplete")) | F12: =IF(AND(ISNUMBER('2) Performance breakdown'!F26),ISNUMBER('2) Performance breakdown'!$C$26)),IFERROR('2) Performance breakdown'!F26-'2) Performance breakdown'!$C$26,"n/a"),IF(OR('2) Performance breakdown'!F26="Invalid",'2) Performance breakdown'!$C$26="Invalid"),"Invalid","Incomplete")) | G12: =IF(AND(ISNUMBER('2) Performance breakdown'!G26),ISNUMBER('2) Performance breakdown'!$C$26)),IFERROR('2) Performance breakdown'!G26-'2) Performance breakdown'!$C$26,"n/a"),IF(OR('2) Performance breakdown'!G26="Invalid",'2) Performance breakdown'!$C$26="Invalid"),"Invalid","Incomplete")) | H12: =IF(AND(ISNUMBER('2) Performance breakdown'!H26),ISNUMBER('2) Performance breakdown'!$C$26)),IFERROR('2) Performance breakdown'!H26-'2) Performance breakdown'!$C$26,"n/a"),IF(OR('2) Performance breakdown'!H26="Invalid",'2) Performance breakdown'!$C$26="Invalid"),"Invalid","Incomplete")) | J12: =IF(AND(ISNUMBER('2) Performance breakdown'!J26),ISNUMBER('2) Performance breakdown'!$C$26)),IFERROR('2) Performance breakdown'!J26-'2) Performance breakdown'!$C$26,"n/a"),IF(OR('2) Performance breakdown'!J26="Invalid",'2) Performance breakdown'!$C$26="Invalid"),"Invalid","Incomplete")) | K12: =IF(AND(ISNUMBER('2) Performance breakdown'!K26),ISNUMBER('2) Performance breakdown'!$C$26)),IFERROR('2) Performance breakdown'!K26-'2) Performance breakdown'!$C$26,"n/a"),IF(OR('2) Performance breakdown'!K26="Invalid",'2) Performance breakdown'!$C$26="Invalid"),"Invalid","Incomplete")) | L12: Scenario salesperson costs − baseline salesperson costs (2) Performance breakdown, row 26)
B13: Total sales costs | C13: =IF(AND(ISNUMBER(Sales_Overhead),ISNUMBER('2) Performance breakdown'!C26)),IFERROR(Sales_Overhead+'2) Performance breakdown'!C26,"n/a"),IF(OR(Sales_Overhead="Invalid",'2) Performance breakdown'!C26="Invalid"),"Invalid","Incomplete")) | E13: =IF(AND(ISNUMBER('2) Performance breakdown'!E26),ISNUMBER(Sales_Overhead)),IFERROR('2) Performance breakdown'!E26+Sales_Overhead,"n/a"),IF(OR('2) Performance breakdown'!E26="Invalid",Sales_Overhead="Invalid"),"Invalid","Incomplete")) | F13: =IF(AND(ISNUMBER('2) Performance breakdown'!F26),ISNUMBER(Sales_Overhead)),IFERROR('2) Performance breakdown'!F26+Sales_Overhead,"n/a"),IF(OR('2) Performance breakdown'!F26="Invalid",Sales_Overhead="Invalid"),"Invalid","Incomplete")) | G13: =IF(AND(ISNUMBER('2) Performance breakdown'!G26),ISNUMBER(Sales_Overhead)),IFERROR('2) Performance breakdown'!G26+Sales_Overhead,"n/a"),IF(OR('2) Performance breakdown'!G26="Invalid",Sales_Overhead="Invalid"),"Invalid","Incomplete")) | H13: =IF(AND(ISNUMBER('2) Performance breakdown'!H26),ISNUMBER(Sales_Overhead)),IFERROR('2) Performance breakdown'!H26+Sales_Overhead,"n/a"),IF(OR('2) Performance breakdown'!H26="Invalid",Sales_Overhead="Invalid"),"Invalid","Incomplete")) | J13: =IF(AND(ISNUMBER('2) Performance breakdown'!J26),ISNUMBER(Sales_Overhead)),IFERROR('2) Performance breakdown'!J26+Sales_Overhead,"n/a"),IF(OR('2) Performance breakdown'!J26="Invalid",Sales_Overhead="Invalid"),"Invalid","Incomplete")) | K13: =IF(AND(ISNUMBER('2) Performance breakdown'!K26),ISNUMBER(Sales_Overhead)),IFERROR('2) Performance breakdown'!K26+Sales_Overhead,"n/a"),IF(OR('2) Performance breakdown'!K26="Invalid",Sales_Overhead="Invalid"),"Invalid","Incomplete")) | L13: Sales overhead (entry sheet) + salesperson costs
B14: Total marketing costs | C14: =IF(ISNUMBER(Marketing),IFERROR(Marketing,"n/a"),IF(Marketing="Invalid","Invalid","Incomplete")) | E14: =IF(ISNUMBER(Marketing),IFERROR(Marketing,"n/a"),IF(Marketing="Invalid","Invalid","Incomplete")) | F14: =IF(ISNUMBER(Marketing),IFERROR(Marketing,"n/a"),IF(Marketing="Invalid","Invalid","Incomplete")) | G14: =IF(ISNUMBER(Marketing),IFERROR(Marketing,"n/a"),IF(Marketing="Invalid","Invalid","Incomplete")) | H14: =IF(ISNUMBER(Marketing),IFERROR(Marketing,"n/a"),IF(Marketing="Invalid","Invalid","Incomplete")) | J14: =IF(ISNUMBER(Marketing),IFERROR(Marketing,"n/a"),IF(Marketing="Invalid","Invalid","Incomplete")) | K14: =IF(ISNUMBER(Marketing),IFERROR(Marketing,"n/a"),IF(Marketing="Invalid","Invalid","Incomplete")) | L14: Marketing (entry sheet); fixed across scenarios
B15: Total sales and marketing costs | C15: =IF(COUNT(C13:C14)=ROWS(C13:C14)*COLUMNS(C13:C14),IFERROR(SUM(C13:C14),"n/a"),IF(COUNTIF(C13:C14,"Invalid")>0,"Invalid","Incomplete")) | E15: =IF(AND(ISNUMBER(E14),ISNUMBER(E13)),IFERROR(E14+E13,"n/a"),IF(OR(E14="Invalid",E13="Invalid"),"Invalid","Incomplete")) | F15: =IF(AND(ISNUMBER(F14),ISNUMBER(F13)),IFERROR(F14+F13,"n/a"),IF(OR(F14="Invalid",F13="Invalid"),"Invalid","Incomplete")) | G15: =IF(AND(ISNUMBER(G14),ISNUMBER(G13)),IFERROR(G14+G13,"n/a"),IF(OR(G14="Invalid",G13="Invalid"),"Invalid","Incomplete")) | H15: =IF(AND(ISNUMBER(H14),ISNUMBER(H13)),IFERROR(H14+H13,"n/a"),IF(OR(H14="Invalid",H13="Invalid"),"Invalid","Incomplete")) | J15: =IF(AND(ISNUMBER(J14),ISNUMBER(J13)),IFERROR(J14+J13,"n/a"),IF(OR(J14="Invalid",J13="Invalid"),"Invalid","Incomplete")) | K15: =IF(AND(ISNUMBER(K14),ISNUMBER(K13)),IFERROR(K14+K13,"n/a"),IF(OR(K14="Invalid",K13="Invalid"),"Invalid","Incomplete")) | L15: Total sales costs + total marketing costs
B17: Operating Expenses
B18: Cost of revenue | C18: =IF(AND(ISNUMBER(C8),ISNUMBER(Cost_Of_Revenue_Pct)),IFERROR(C8*Cost_Of_Revenue_Pct,"n/a"),IF(OR(C8="Invalid",Cost_Of_Revenue_Pct="Invalid"),"Invalid","Incomplete")) | E18: =IF(AND(ISNUMBER(E8),ISNUMBER(Cost_Of_Revenue_Pct)),IFERROR(E8*Cost_Of_Revenue_Pct,"n/a"),IF(OR(E8="Invalid",Cost_Of_Revenue_Pct="Invalid"),"Invalid","Incomplete")) | F18: =IF(AND(ISNUMBER(F8),ISNUMBER(Cost_Of_Revenue_Pct)),IFERROR(F8*Cost_Of_Revenue_Pct,"n/a"),IF(OR(F8="Invalid",Cost_Of_Revenue_Pct="Invalid"),"Invalid","Incomplete")) | G18: =IF(AND(ISNUMBER(G8),ISNUMBER(Cost_Of_Revenue_Pct)),IFERROR(G8*Cost_Of_Revenue_Pct,"n/a"),IF(OR(G8="Invalid",Cost_Of_Revenue_Pct="Invalid"),"Invalid","Incomplete")) | H18: =IF(AND(ISNUMBER(H8),ISNUMBER(Cost_Of_Revenue_Pct)),IFERROR(H8*Cost_Of_Revenue_Pct,"n/a"),IF(OR(H8="Invalid",Cost_Of_Revenue_Pct="Invalid"),"Invalid","Incomplete")) | J18: =IF(AND(ISNUMBER(J8),ISNUMBER(Cost_Of_Revenue_Pct)),IFERROR(J8*Cost_Of_Revenue_Pct,"n/a"),IF(OR(J8="Invalid",Cost_Of_Revenue_Pct="Invalid"),"Invalid","Incomplete")) | K18: =IF(AND(ISNUMBER(K8),ISNUMBER(Cost_Of_Revenue_Pct)),IFERROR(K8*Cost_Of_Revenue_Pct,"n/a"),IF(OR(K8="Invalid",Cost_Of_Revenue_Pct="Invalid"),"Invalid","Incomplete")) | L18: Revenue × cost of revenue ratio (entry sheet)
B19: Research and development | C19: =IF(AND(ISNUMBER(C8),ISNUMBER(RnD_Pct)),IFERROR(C8*RnD_Pct,"n/a"),IF(OR(C8="Invalid",RnD_Pct="Invalid"),"Invalid","Incomplete")) | E19: =IF(AND(ISNUMBER(E8),ISNUMBER(RnD_Pct)),IFERROR(E8*RnD_Pct,"n/a"),IF(OR(E8="Invalid",RnD_Pct="Invalid"),"Invalid","Incomplete")) | F19: =IF(AND(ISNUMBER(F8),ISNUMBER(RnD_Pct)),IFERROR(F8*RnD_Pct,"n/a"),IF(OR(F8="Invalid",RnD_Pct="Invalid"),"Invalid","Incomplete")) | G19: =IF(AND(ISNUMBER(G8),ISNUMBER(RnD_Pct)),IFERROR(G8*RnD_Pct,"n/a"),IF(OR(G8="Invalid",RnD_Pct="Invalid"),"Invalid","Incomplete")) | H19: =IF(AND(ISNUMBER(H8),ISNUMBER(RnD_Pct)),IFERROR(H8*RnD_Pct,"n/a"),IF(OR(H8="Invalid",RnD_Pct="Invalid"),"Invalid","Incomplete")) | J19: =IF(AND(ISNUMBER(J8),ISNUMBER(RnD_Pct)),IFERROR(J8*RnD_Pct,"n/a"),IF(OR(J8="Invalid",RnD_Pct="Invalid"),"Invalid","Incomplete")) | K19: =IF(AND(ISNUMBER(K8),ISNUMBER(RnD_Pct)),IFERROR(K8*RnD_Pct,"n/a"),IF(OR(K8="Invalid",RnD_Pct="Invalid"),"Invalid","Incomplete")) | L19: Revenue × R&D ratio (entry sheet)
B20: Sales and marketing | C20: =IF(AND(ISNUMBER(C13),ISNUMBER(C14)),IFERROR(C13+C14,"n/a"),IF(OR(C13="Invalid",C14="Invalid"),"Invalid","Incomplete")) | E20: =IF(AND(ISNUMBER(E13),ISNUMBER(E14)),IFERROR(E13+E14,"n/a"),IF(OR(E13="Invalid",E14="Invalid"),"Invalid","Incomplete")) | F20: =IF(AND(ISNUMBER(F13),ISNUMBER(F14)),IFERROR(F13+F14,"n/a"),IF(OR(F13="Invalid",F14="Invalid"),"Invalid","Incomplete")) | G20: =IF(AND(ISNUMBER(G13),ISNUMBER(G14)),IFERROR(G13+G14,"n/a"),IF(OR(G13="Invalid",G14="Invalid"),"Invalid","Incomplete")) | H20: =IF(AND(ISNUMBER(H13),ISNUMBER(H14)),IFERROR(H13+H14,"n/a"),IF(OR(H13="Invalid",H14="Invalid"),"Invalid","Incomplete")) | J20: =IF(AND(ISNUMBER(J13),ISNUMBER(J14)),IFERROR(J13+J14,"n/a"),IF(OR(J13="Invalid",J14="Invalid"),"Invalid","Incomplete")) | K20: =IF(AND(ISNUMBER(K13),ISNUMBER(K14)),IFERROR(K13+K14,"n/a"),IF(OR(K13="Invalid",K14="Invalid"),"Invalid","Incomplete")) | L20: Total sales costs + total marketing costs
B21: General and administrative | C21: =IF(AND(ISNUMBER(C8),ISNUMBER(GnA_Pct)),IFERROR(C8*GnA_Pct,"n/a"),IF(OR(C8="Invalid",GnA_Pct="Invalid"),"Invalid","Incomplete")) | E21: =IF(AND(ISNUMBER(E8),ISNUMBER(GnA_Pct)),IFERROR(E8*GnA_Pct,"n/a"),IF(OR(E8="Invalid",GnA_Pct="Invalid"),"Invalid","Incomplete")) | F21: =IF(AND(ISNUMBER(F8),ISNUMBER(GnA_Pct)),IFERROR(F8*GnA_Pct,"n/a"),IF(OR(F8="Invalid",GnA_Pct="Invalid"),"Invalid","Incomplete")) | G21: =IF(AND(ISNUMBER(G8),ISNUMBER(GnA_Pct)),IFERROR(G8*GnA_Pct,"n/a"),IF(OR(G8="Invalid",GnA_Pct="Invalid"),"Invalid","Incomplete")) | H21: =IF(AND(ISNUMBER(H8),ISNUMBER(GnA_Pct)),IFERROR(H8*GnA_Pct,"n/a"),IF(OR(H8="Invalid",GnA_Pct="Invalid"),"Invalid","Incomplete")) | J21: =IF(AND(ISNUMBER(J8),ISNUMBER(GnA_Pct)),IFERROR(J8*GnA_Pct,"n/a"),IF(OR(J8="Invalid",GnA_Pct="Invalid"),"Invalid","Incomplete")) | K21: =IF(AND(ISNUMBER(K8),ISNUMBER(GnA_Pct)),IFERROR(K8*GnA_Pct,"n/a"),IF(OR(K8="Invalid",GnA_Pct="Invalid"),"Invalid","Incomplete")) | L21: Revenue × G&A ratio (entry sheet)
B22: Total operating expenses | C22: =IF(COUNT(C18:C21)=ROWS(C18:C21)*COLUMNS(C18:C21),IFERROR(SUM(C18:C21),"n/a"),IF(COUNTIF(C18:C21,"Invalid")>0,"Invalid","Incomplete")) | E22: =IF(COUNT(E18:E21)=ROWS(E18:E21)*COLUMNS(E18:E21),IFERROR(SUM(E18:E21),"n/a"),IF(COUNTIF(E18:E21,"Invalid")>0,"Invalid","Incomplete")) | F22: =IF(COUNT(F18:F21)=ROWS(F18:F21)*COLUMNS(F18:F21),IFERROR(SUM(F18:F21),"n/a"),IF(COUNTIF(F18:F21,"Invalid")>0,"Invalid","Incomplete")) | G22: =IF(COUNT(G18:G21)=ROWS(G18:G21)*COLUMNS(G18:G21),IFERROR(SUM(G18:G21),"n/a"),IF(COUNTIF(G18:G21,"Invalid")>0,"Invalid","Incomplete")) | H22: =IF(COUNT(H18:H21)=ROWS(H18:H21)*COLUMNS(H18:H21),IFERROR(SUM(H18:H21),"n/a"),IF(COUNTIF(H18:H21,"Invalid")>0,"Invalid","Incomplete")) | J22: =IF(COUNT(J18:J21)=ROWS(J18:J21)*COLUMNS(J18:J21),IFERROR(SUM(J18:J21),"n/a"),IF(COUNTIF(J18:J21,"Invalid")>0,"Invalid","Incomplete")) | K22: =IF(COUNT(K18:K21)=ROWS(K18:K21)*COLUMNS(K18:K21),IFERROR(SUM(K18:K21),"n/a"),IF(COUNTIF(K18:K21,"Invalid")>0,"Invalid","Incomplete")) | L22: Cost of revenue + R&D + sales and marketing + G&A
B23: Operating Income | C23: =IF(AND(ISNUMBER(C8),ISNUMBER(C22)),IFERROR(C8-C22,"n/a"),IF(OR(C8="Invalid",C22="Invalid"),"Invalid","Incomplete")) | E23: =IF(AND(ISNUMBER(E8),ISNUMBER(E22)),IFERROR(E8-E22,"n/a"),IF(OR(E8="Invalid",E22="Invalid"),"Invalid","Incomplete")) | F23: =IF(AND(ISNUMBER(F8),ISNUMBER(F22)),IFERROR(F8-F22,"n/a"),IF(OR(F8="Invalid",F22="Invalid"),"Invalid","Incomplete")) | G23: =IF(AND(ISNUMBER(G8),ISNUMBER(G22)),IFERROR(G8-G22,"n/a"),IF(OR(G8="Invalid",G22="Invalid"),"Invalid","Incomplete")) | H23: =IF(AND(ISNUMBER(H8),ISNUMBER(H22)),IFERROR(H8-H22,"n/a"),IF(OR(H8="Invalid",H22="Invalid"),"Invalid","Incomplete")) | J23: =IF(AND(ISNUMBER(J8),ISNUMBER(J22)),IFERROR(J8-J22,"n/a"),IF(OR(J8="Invalid",J22="Invalid"),"Invalid","Incomplete")) | K23: =IF(AND(ISNUMBER(K8),ISNUMBER(K22)),IFERROR(K8-K22,"n/a"),IF(OR(K8="Invalid",K22="Invalid"),"Invalid","Incomplete")) | L23: Revenue − total operating expenses
B24: Change in operating income from baseline | E24: =IF(AND(ISNUMBER(E23),ISNUMBER($C$23)),IFERROR(E23-$C$23,"n/a"),IF(OR(E23="Invalid",$C$23="Invalid"),"Invalid","Incomplete")) | F24: =IF(AND(ISNUMBER(F23),ISNUMBER($C$23)),IFERROR(F23-$C$23,"n/a"),IF(OR(F23="Invalid",$C$23="Invalid"),"Invalid","Incomplete")) | G24: =IF(AND(ISNUMBER(G23),ISNUMBER($C$23)),IFERROR(G23-$C$23,"n/a"),IF(OR(G23="Invalid",$C$23="Invalid"),"Invalid","Incomplete")) | H24: =IF(AND(ISNUMBER(H23),ISNUMBER($C$23)),IFERROR(H23-$C$23,"n/a"),IF(OR(H23="Invalid",$C$23="Invalid"),"Invalid","Incomplete")) | J24: =IF(AND(ISNUMBER(J23),ISNUMBER($C$23)),IFERROR(J23-$C$23,"n/a"),IF(OR(J23="Invalid",$C$23="Invalid"),"Invalid","Incomplete")) | K24: =IF(AND(ISNUMBER(K23),ISNUMBER($C$23)),IFERROR(K23-$C$23,"n/a"),IF(OR(K23="Invalid",$C$23="Invalid"),"Invalid","Incomplete")) | L24: Scenario operating income − baseline operating income. Drivers and the full bridge: sheet Compare
B25: Metrics
B26: Percentage net gain | E26: =IF(AND(ISNUMBER(E9),ISNUMBER(E12),ISNUMBER('2) Performance breakdown'!$C$25)),IFERROR((E9-E12)/'2) Performance breakdown'!$C$25,"n/a"),IF(OR(E9="Invalid",E12="Invalid",'2) Performance breakdown'!$C$25="Invalid"),"Invalid","Incomplete")) | F26: =IF(AND(ISNUMBER(F9),ISNUMBER(F12),ISNUMBER('2) Performance breakdown'!$C$25)),IFERROR((F9-F12)/'2) Performance breakdown'!$C$25,"n/a"),IF(OR(F9="Invalid",F12="Invalid",'2) Performance breakdown'!$C$25="Invalid"),"Invalid","Incomplete")) | G26: =IF(AND(ISNUMBER(G9),ISNUMBER(G12),ISNUMBER('2) Performance breakdown'!$C$25)),IFERROR((G9-G12)/'2) Performance breakdown'!$C$25,"n/a"),IF(OR(G9="Invalid",G12="Invalid",'2) Performance breakdown'!$C$25="Invalid"),"Invalid","Incomplete")) | H26: =IF(AND(ISNUMBER(H9),ISNUMBER(H12),ISNUMBER('2) Performance breakdown'!$C$25)),IFERROR((H9-H12)/'2) Performance breakdown'!$C$25,"n/a"),IF(OR(H9="Invalid",H12="Invalid",'2) Performance breakdown'!$C$25="Invalid"),"Invalid","Incomplete")) | J26: =IF(AND(ISNUMBER(J9),ISNUMBER(J12),ISNUMBER('2) Performance breakdown'!$C$25)),IFERROR((J9-J12)/'2) Performance breakdown'!$C$25,"n/a"),IF(OR(J9="Invalid",J12="Invalid",'2) Performance breakdown'!$C$25="Invalid"),"Invalid","Incomplete")) | K26: =IF(AND(ISNUMBER(K9),ISNUMBER(K12),ISNUMBER('2) Performance breakdown'!$C$25)),IFERROR((K9-K12)/'2) Performance breakdown'!$C$25,"n/a"),IF(OR(K9="Invalid",K12="Invalid",'2) Performance breakdown'!$C$25="Invalid"),"Invalid","Incomplete")) | L26: (Increase in revenue − increase in sales costs) ÷ baseline revenue
B27: Sales and marketing ROI | C27: =IF(AND(ISNUMBER(C8),ISNUMBER(C15)),IFERROR((C8-C15)/C15,"n/a"),IF(OR(C8="Invalid",C15="Invalid"),"Invalid","Incomplete")) | E27: =IF(AND(ISNUMBER(E8),ISNUMBER(E15)),IFERROR((E8-E15)/E15,"n/a"),IF(OR(E8="Invalid",E15="Invalid"),"Invalid","Incomplete")) | F27: =IF(AND(ISNUMBER(F8),ISNUMBER(F15)),IFERROR((F8-F15)/F15,"n/a"),IF(OR(F8="Invalid",F15="Invalid"),"Invalid","Incomplete")) | G27: =IF(AND(ISNUMBER(G8),ISNUMBER(G15)),IFERROR((G8-G15)/G15,"n/a"),IF(OR(G8="Invalid",G15="Invalid"),"Invalid","Incomplete")) | H27: =IF(AND(ISNUMBER(H8),ISNUMBER(H15)),IFERROR((H8-H15)/H15,"n/a"),IF(OR(H8="Invalid",H15="Invalid"),"Invalid","Incomplete")) | J27: =IF(AND(ISNUMBER(J8),ISNUMBER(J15)),IFERROR((J8-J15)/J15,"n/a"),IF(OR(J8="Invalid",J15="Invalid"),"Invalid","Incomplete")) | K27: =IF(AND(ISNUMBER(K8),ISNUMBER(K15)),IFERROR((K8-K15)/K15,"n/a"),IF(OR(K8="Invalid",K15="Invalid"),"Invalid","Incomplete")) | L27: (Revenue − sales and marketing costs) ÷ sales and marketing costs
B29: Assumptions — This spreadsheet is designed to provide you with a baseline analysis to determine the impact of sales productivity investments on your company's income statement. If you know the actual amounts for the other categories (G&A, R&D, COGS) then you can enter those figures directly into the corresponding cells. However, you can see this information is already populated. The table on the left contains industry average % of revenue metrics that are used to populate the data in this sheet. The three ratios are entered on 1) Data entry (rows 59–61) and shown here.
B30: Cost of revenue | C30: =IF(ISNUMBER(Cost_Of_Revenue_Pct),IFERROR(Cost_Of_Revenue_Pct,"n/a"),IF(Cost_Of_Revenue_Pct="Invalid","Invalid","Incomplete"))
B31: R&D | C31: =IF(ISNUMBER(RnD_Pct),IFERROR(RnD_Pct,"n/a"),IF(RnD_Pct="Invalid","Invalid","Incomplete"))
B32: G&A (other) | C32: =IF(ISNUMBER(GnA_Pct),IFERROR(GnA_Pct,"n/a"),IF(GnA_Pct="Invalid","Invalid","Incomplete"))

Sheet Compare
B2: Compare: what each scenario changed, and what the change did
B3: © 2000–2026 Growth Enablement. All rights reserved. Sales Capacity Model: originated 2000, accuracy audit by Ernst & Young 2003, this edition 2026.
B4: ='3) Impact Analysis'!B4
B6: 1. What each scenario changed (shaded where it differs from the baseline)
B7: Driver | C7: Baseline | E7: Hire more sales people | F7: Increase Close Rate | G7: Decrease Sales Cycle Time | H7: Increase Average Revenue/ Transaction | J7: Increase close and deal size; decrease cycle | K7: Improve all scenarios | L7: How it is calculated
B8: Territories | C8: ='2) Performance breakdown'!C9 | E8: ='2) Performance breakdown'!E9 | F8: ='2) Performance breakdown'!F9 | G8: ='2) Performance breakdown'!G9 | H8: ='2) Performance breakdown'!H9 | J8: ='2) Performance breakdown'!J9 | K8: ='2) Performance breakdown'!K9 | L8: From 2) Performance breakdown, row 9
B9: Close rate | C9: ='2) Performance breakdown'!C19 | E9: ='2) Performance breakdown'!E19 | F9: ='2) Performance breakdown'!F19 | G9: ='2) Performance breakdown'!G19 | H9: ='2) Performance breakdown'!H19 | J9: ='2) Performance breakdown'!J19 | K9: ='2) Performance breakdown'!K19 | L9: From 2) Performance breakdown, row 19
B10: Sales cycle (months) | C10: ='2) Performance breakdown'!C17 | E10: ='2) Performance breakdown'!E17 | F10: ='2) Performance breakdown'!F17 | G10: ='2) Performance breakdown'!G17 | H10: ='2) Performance breakdown'!H17 | J10: ='2) Performance breakdown'!J17 | K10: ='2) Performance breakdown'!K17 | L10: From 2) Performance breakdown, row 17
B11: Deal size | C11: ='2) Performance breakdown'!C10 | E11: ='2) Performance breakdown'!E10 | F11: ='2) Performance breakdown'!F10 | G11: ='2) Performance breakdown'!G10 | H11: ='2) Performance breakdown'!H10 | J11: ='2) Performance breakdown'!J10 | K11: ='2) Performance breakdown'!K10 | L11: From 2) Performance breakdown, row 10
B13: 2. What it did: each line's effect on operating income (a bridge from baseline to scenario)
B14: Line | C14: Baseline amount | E14: Hire more sales people: effect | F14: Increase Close Rate: effect | G14: Decrease Sales Cycle Time: effect | H14: Increase Average Revenue/ Transaction: effect | J14: Increase close and deal size; decrease cycle: effect | K14: Improve all scenarios: effect | L14: How it is calculated
B15: Revenue | C15: =IF(ISNUMBER('3) Impact Analysis'!C8),IFERROR('3) Impact Analysis'!C8,"n/a"),IF('3) Impact Analysis'!C8="Invalid","Invalid","Incomplete")) | E15: =IF(AND(ISNUMBER('3) Impact Analysis'!E8),ISNUMBER('3) Impact Analysis'!$C$8)),IFERROR('3) Impact Analysis'!E8-'3) Impact Analysis'!$C$8,"n/a"),IF(OR('3) Impact Analysis'!E8="Invalid",'3) Impact Analysis'!$C$8="Invalid"),"Invalid","Incomplete")) | F15: =IF(AND(ISNUMBER('3) Impact Analysis'!F8),ISNUMBER('3) Impact Analysis'!$C$8)),IFERROR('3) Impact Analysis'!F8-'3) Impact Analysis'!$C$8,"n/a"),IF(OR('3) Impact Analysis'!F8="Invalid",'3) Impact Analysis'!$C$8="Invalid"),"Invalid","Incomplete")) | G15: =IF(AND(ISNUMBER('3) Impact Analysis'!G8),ISNUMBER('3) Impact Analysis'!$C$8)),IFERROR('3) Impact Analysis'!G8-'3) Impact Analysis'!$C$8,"n/a"),IF(OR('3) Impact Analysis'!G8="Invalid",'3) Impact Analysis'!$C$8="Invalid"),"Invalid","Incomplete")) | H15: =IF(AND(ISNUMBER('3) Impact Analysis'!H8),ISNUMBER('3) Impact Analysis'!$C$8)),IFERROR('3) Impact Analysis'!H8-'3) Impact Analysis'!$C$8,"n/a"),IF(OR('3) Impact Analysis'!H8="Invalid",'3) Impact Analysis'!$C$8="Invalid"),"Invalid","Incomplete")) | J15: =IF(AND(ISNUMBER('3) Impact Analysis'!J8),ISNUMBER('3) Impact Analysis'!$C$8)),IFERROR('3) Impact Analysis'!J8-'3) Impact Analysis'!$C$8,"n/a"),IF(OR('3) Impact Analysis'!J8="Invalid",'3) Impact Analysis'!$C$8="Invalid"),"Invalid","Incomplete")) | K15: =IF(AND(ISNUMBER('3) Impact Analysis'!K8),ISNUMBER('3) Impact Analysis'!$C$8)),IFERROR('3) Impact Analysis'!K8-'3) Impact Analysis'!$C$8,"n/a"),IF(OR('3) Impact Analysis'!K8="Invalid",'3) Impact Analysis'!$C$8="Invalid"),"Invalid","Incomplete")) | L15: + change in revenue
B16: Cost of revenue | C16: =IF(ISNUMBER('3) Impact Analysis'!C18),IFERROR('3) Impact Analysis'!C18,"n/a"),IF('3) Impact Analysis'!C18="Invalid","Invalid","Incomplete")) | E16: =IF(AND(ISNUMBER('3) Impact Analysis'!E18),ISNUMBER('3) Impact Analysis'!$C$18)),IFERROR(-('3) Impact Analysis'!E18-'3) Impact Analysis'!$C$18),"n/a"),IF(OR('3) Impact Analysis'!E18="Invalid",'3) Impact Analysis'!$C$18="Invalid"),"Invalid","Incomplete")) | F16: =IF(AND(ISNUMBER('3) Impact Analysis'!F18),ISNUMBER('3) Impact Analysis'!$C$18)),IFERROR(-('3) Impact Analysis'!F18-'3) Impact Analysis'!$C$18),"n/a"),IF(OR('3) Impact Analysis'!F18="Invalid",'3) Impact Analysis'!$C$18="Invalid"),"Invalid","Incomplete")) | G16: =IF(AND(ISNUMBER('3) Impact Analysis'!G18),ISNUMBER('3) Impact Analysis'!$C$18)),IFERROR(-('3) Impact Analysis'!G18-'3) Impact Analysis'!$C$18),"n/a"),IF(OR('3) Impact Analysis'!G18="Invalid",'3) Impact Analysis'!$C$18="Invalid"),"Invalid","Incomplete")) | H16: =IF(AND(ISNUMBER('3) Impact Analysis'!H18),ISNUMBER('3) Impact Analysis'!$C$18)),IFERROR(-('3) Impact Analysis'!H18-'3) Impact Analysis'!$C$18),"n/a"),IF(OR('3) Impact Analysis'!H18="Invalid",'3) Impact Analysis'!$C$18="Invalid"),"Invalid","Incomplete")) | J16: =IF(AND(ISNUMBER('3) Impact Analysis'!J18),ISNUMBER('3) Impact Analysis'!$C$18)),IFERROR(-('3) Impact Analysis'!J18-'3) Impact Analysis'!$C$18),"n/a"),IF(OR('3) Impact Analysis'!J18="Invalid",'3) Impact Analysis'!$C$18="Invalid"),"Invalid","Incomplete")) | K16: =IF(AND(ISNUMBER('3) Impact Analysis'!K18),ISNUMBER('3) Impact Analysis'!$C$18)),IFERROR(-('3) Impact Analysis'!K18-'3) Impact Analysis'!$C$18),"n/a"),IF(OR('3) Impact Analysis'!K18="Invalid",'3) Impact Analysis'!$C$18="Invalid"),"Invalid","Incomplete")) | L16: − change in cost of revenue
B17: Research and development | C17: =IF(ISNUMBER('3) Impact Analysis'!C19),IFERROR('3) Impact Analysis'!C19,"n/a"),IF('3) Impact Analysis'!C19="Invalid","Invalid","Incomplete")) | E17: =IF(AND(ISNUMBER('3) Impact Analysis'!E19),ISNUMBER('3) Impact Analysis'!$C$19)),IFERROR(-('3) Impact Analysis'!E19-'3) Impact Analysis'!$C$19),"n/a"),IF(OR('3) Impact Analysis'!E19="Invalid",'3) Impact Analysis'!$C$19="Invalid"),"Invalid","Incomplete")) | F17: =IF(AND(ISNUMBER('3) Impact Analysis'!F19),ISNUMBER('3) Impact Analysis'!$C$19)),IFERROR(-('3) Impact Analysis'!F19-'3) Impact Analysis'!$C$19),"n/a"),IF(OR('3) Impact Analysis'!F19="Invalid",'3) Impact Analysis'!$C$19="Invalid"),"Invalid","Incomplete")) | G17: =IF(AND(ISNUMBER('3) Impact Analysis'!G19),ISNUMBER('3) Impact Analysis'!$C$19)),IFERROR(-('3) Impact Analysis'!G19-'3) Impact Analysis'!$C$19),"n/a"),IF(OR('3) Impact Analysis'!G19="Invalid",'3) Impact Analysis'!$C$19="Invalid"),"Invalid","Incomplete")) | H17: =IF(AND(ISNUMBER('3) Impact Analysis'!H19),ISNUMBER('3) Impact Analysis'!$C$19)),IFERROR(-('3) Impact Analysis'!H19-'3) Impact Analysis'!$C$19),"n/a"),IF(OR('3) Impact Analysis'!H19="Invalid",'3) Impact Analysis'!$C$19="Invalid"),"Invalid","Incomplete")) | J17: =IF(AND(ISNUMBER('3) Impact Analysis'!J19),ISNUMBER('3) Impact Analysis'!$C$19)),IFERROR(-('3) Impact Analysis'!J19-'3) Impact Analysis'!$C$19),"n/a"),IF(OR('3) Impact Analysis'!J19="Invalid",'3) Impact Analysis'!$C$19="Invalid"),"Invalid","Incomplete")) | K17: =IF(AND(ISNUMBER('3) Impact Analysis'!K19),ISNUMBER('3) Impact Analysis'!$C$19)),IFERROR(-('3) Impact Analysis'!K19-'3) Impact Analysis'!$C$19),"n/a"),IF(OR('3) Impact Analysis'!K19="Invalid",'3) Impact Analysis'!$C$19="Invalid"),"Invalid","Incomplete")) | L17: − change in R&D
